Workbook

Sheet INV
B1: CÔNG TY TNHH HẢI AN NEW MATERIAL HẬU GIANG
B2: SỐ 168, ẤP TẦM VU 1, XÃ THẠNH HÒA, TP CẦN THƠ, VIỆT NAM.
B3: COMMERICAL INVOICE
C4: Bên thuê gia công : | D4: CÔNG TY TNHH KINGMAKER III (VIỆT NAM) FOOTWEAR | I4: INVOICE NO.: | J4: KMHD-NEW2026-0233
C5: Địa chỉ : | D5: SỐ 1, ĐƯỜNG 4A, KCN VIỆT NAM SINGAPORE, | I5: DATE: | J5: SEP 05,2026
D6: XÃ THỌ PHONG, TỈNH QUẢNG NGÃI, VIỆT NAM | I6: Hợp đồng: KM-HANEW/01-2025
I7: Điều kiện giao hàng: | J7: DAP
C8: Bên nhận gia công: | D8: CÔNG TY TNHH HẢI AN NEW MATERIAL HẬU GIANG | I8: Phương thức thanh toán: | J8: T/T
C9: Địa chỉ : | D9: SỐ 168, ẤP TẦM VU 1, XÃ THẠNH HÒA | I9: Nước đến: | J9: VIETNAM
D10: TP. CẦN THƠ, VIỆT NAM
B11: STT | C11: MÃ HÀNG | D11: MÔ TẢ | E11: SỐ LƯỢNG | F11: ĐVT | G11: ĐƠN GIÁ | I11: THÀNH TIỀN
G12: CMT (USD) | H12: DAP (USD) | I12: CMT (USD) | J12: DAP (USD)
B13: =IF(C13="","",SUBTOTAL(103,$C$13:C13)) -> 0 | C13: 42072-030 (KM3.PO5.26) | D13: Giày có mũ giày bằng vật liệu dệt và đế ngoài bằng plastic, mũi giày không được gắn bảo vệ. Hàng mới 100%. | F13: đôi | G13: 3.2 | H13: 8.2 | I13: =G13*E13 -> 0 | J13: =H13*E13 -> 0 | K13: =E13/12 -> 0
B14: =IF(C14="","",SUBTOTAL(103,$C$13:C14)) -> 0 | C14: 42072-267 (KM3.PO5.26) | D14: Giày có mũ giày bằng vật liệu dệt và đế ngoài bằng plastic, mũi giày không được gắn bảo vệ. Hàng mới 100%. | F14: đôi | G14: 3.2 | H14: 8.2 | I14: =G14*E14 -> 0 | J14: =H14*E14 -> 0 | K14: =E14/12 -> 0
B15: =IF(C15="","",SUBTOTAL(103,$C$13:C15)) -> 0 | C15: 42072-410 (KM3.PO5.26) | D15: Giày có mũ giày bằng vật liệu dệt và đế ngoài bằng plastic, mũi giày không được gắn bảo vệ. Hàng mới 100%. | F15: đôi | G15: 3.2 | H15: 8.2 | I15: =G15*E15 -> 0 | J15: =H15*E15 -> 0 | K15: =E15/12 -> 0
A16: 7 | B16: =IF(C16="","",SUBTOTAL(103,$C$13:C16)) -> 0 | C16: 40700-060 (KM3.PO5.26) | D16: Giày có mũ giày bằng vật liệu dệt và đế ngoài bằng plastic, mũi giày không được gắn bảo vệ. Hàng mới 100%. | F16: đôi | G16: 3 | H16: 8.1 | I16: =G16*E16 -> 0 | J16: =H16*E16 -> 0 | K16: =E16/12 -> 0
B17: =IF(C17="","",SUBTOTAL(103,$C$13:C17)) -> 0 | C17: 42073-030 (KM3.PO5.26) | D17: Giày có mũ giày bằng vật liệu dệt và đế ngoài bằng plastic, mũi giày không được gắn bảo vệ. Hàng mới 100%. | F17: đôi | G17: 3.2 | H17: 8.2 | I17: =G17*E17 -> 0 | J17: =H17*E17 -> 0 | K17: =E17/12 -> 0
B18: =IF(C18="","",SUBTOTAL(103,$C$13:C18)) -> 0 | C18: 40700-007 (KM3.PO5.26) | D18: Giày có mũ giày bằng vật liệu dệt và đế ngoài bằng plastic, mũi giày không được gắn bảo vệ. Hàng mới 100%. | F18: đôi | G18: 3 | H18: 8.1 | I18: =G18*E18 -> 0 | J18: =H18*E18 -> 0 | K18: =E18/12 -> 0
A19: 10 | B19: =IF(C19="","",SUBTOTAL(103,$C$13:C19)) -> 0 | C19: 40700-066 (KM3.PO5.26) | D19: Giày có mũ giày bằng vật liệu dệt và đế ngoài bằng plastic, mũi giày không được gắn bảo vệ. Hàng mới 100%. | F19: đôi | G19: 3 | H19: 8.1 | I19: =G19*E19 -> 0 | J19: =H19*E19 -> 0 | K19: =E19/12 -> 0
A20: 11 | B20: =IF(C20="","",SUBTOTAL(103,$C$13:C20)) -> 0 | C20: 40700-410 (KM3.PO5.26) | D20: Giày có mũ giày bằng vật liệu dệt và đế ngoài bằng plastic, mũi giày không được gắn bảo vệ. Hàng mới 100%. | F20: đôi | G20: 3 | H20: 8.1 | I20: =G20*E20 -> 0 | J20: =H20*E20 -> 0 | K20: =E20/12 -> 0
A21: 12 | B21: =IF(C21="","",SUBTOTAL(103,$C$13:C21)) -> 0 | C21: 42072-066 (KM3.PO5.26) | D21: Giày có mũ giày bằng vật liệu dệt và đế ngoài bằng plastic, mũi giày không được gắn bảo vệ. Hàng mới 100%. | F21: đôi | G21: 3.2 | H21: 8.2 | I21: =G21*E21 -> 0 | J21: =H21*E21 -> 0 | K21: =E21/12 -> 0
A22: 13 | B22: =IF(C22="","",SUBTOTAL(103,$C$13:C22)) -> 0 | C22: 42073-060 (KM3.PO5.26) | D22: Giày có mũ giày bằng vật liệu dệt và đế ngoài bằng plastic, mũi giày không được gắn bảo vệ. Hàng mới 100%. | F22: đôi | G22: 3.2 | H22: 8.2 | I22: =G22*E22 -> 0 | J22: =H22*E22 -> 0 | K22: =E22/12 -> 0
A23: 14 | B23: =IF(C23="","",SUBTOTAL(103,$C$13:C23)) -> 0 | C23: 42073-410 (KM3.PO5.26) | D23: Giày có mũ giày bằng vật liệu dệt và đế ngoài bằng plastic, mũi giày không được gắn bảo vệ. Hàng mới 100%. | F23: đôi | G23: 3.2 | H23: 8.2 | I23: =G23*E23 -> 0 | J23: =H23*E23 -> 0 | K23: =E23/12 -> 0
B24: =IF(C24="","",SUBTOTAL(103,$C$13:C24)) -> 0 | C24: 42072-060 (KM3.PO5.26) | D24: Giày có mũ giày bằng vật liệu dệt và đế ngoài bằng plastic, mũi giày không được gắn bảo vệ. Hàng mới 100%. | F24: đôi | G24: 3.2 | H24: 8.2 | I24: =G24*E24 -> 0 | J24: =H24*E24 -> 0 | K24: =E24/12 -> 0
B25: =IF(C25="","",SUBTOTAL(103,$C$13:C25)) -> 0 | C25: 45187-1WQ (KM3.PO5.26) | D25: Giày có mũ giày bằng vật liệu dệt và đế ngoài bằng plastic, mũi giày không được gắn bảo vệ. Hàng mới 100%. | F25: đôi | G25: 3.02 | H25: 8.2 | I25: =G25*E25 -> 0 | J25: =H25*E25 -> 0
B26: =IF(C26="","",SUBTOTAL(103,$C$13:C26)) -> 0 | C26: 45187-3AW (KM3.PO5.26) | D26: Giày có mũ giày bằng vật liệu dệt và đế ngoài bằng plastic, mũi giày không được gắn bảo vệ. Hàng mới 100%. | F26: đôi | G26: 3.02 | H26: 8.2 | I26: =G26*E26 -> 0 | J26: =H26*E26 -> 0 | K26: =E26/12 -> 0
B27: =IF(C27="","",SUBTOTAL(103,$C$13:C27)) -> 0 | C27: 42073-066 (KM3.PO5.26) | D27: Giày có mũ giày bằng vật liệu dệt và đế ngoài bằng plastic, mũi giày không được gắn bảo vệ. Hàng mới 100%. | F27: đôi | G27: 3.2 | H27: 8.2 | I27: =G27*E27 -> 0 | J27: =H27*E27 -> 0 | K27: =E27/12 -> 0
B28: =IF(C28="","",SUBTOTAL(103,$C$13:C28)) -> 0 | C28: 45777-7BR (KM3.PO5.26) | D28: Giày có mũ giày bằng vật liệu dệt và đế ngoài bằng plastic, mũi giày không được gắn bảo vệ. Hàng mới 100%. | F28: đôi | G28: 2.99 | H28: 8 | I28: =G28*E28 -> 0 | J28: =H28*E28 -> 0 | K28: =E28/12 -> 0
B29: =IF(C29="","",SUBTOTAL(103,$C$13:C29)) -> 0 | C29: 40700-143 (KM3.PO5.26) | D29: Giày có mũ giày bằng vật liệu dệt và đế ngoài bằng plastic, mũi giày không được gắn bảo vệ. Hàng mới 100%. | F29: đôi | G29: 3 | H29: 8.1 | I29: =G29*E29 -> 0 | J29: =H29*E29 -> 0
B30: =IF(C30="","",SUBTOTAL(103,$C$13:C30)) -> 0 | C30: 45428-2LX.G (KM3.PO5.26) | D30: Giày có mũ giày bằng vật liệu dệt và đế ngoài bằng plastic, mũi giày không được gắn bảo vệ. Hàng mới 100%. | F30: đôi | G30: 1.16 | H30: 8.1 | I30: =G30*E30 -> 0 | J30: =H30*E30 -> 0 | K30: =E30/12 -> 0
B31: =IF(C31="","",SUBTOTAL(103,$C$13:C31)) -> 1 | C31: 40902-0MX.G (KM3.PO5.26) | D31: Giày có mũ giày bằng vật liệu dệt và đế ngoài bằng plastic, mũi giày không được gắn bảo vệ. Hàng mới 100%. | E31: 2148 | F31: đôi | G31: 1.16 | H31: 8.1 | I31: =G31*E31 -> 2491.68 | J31: =H31*E31 -> 17398.8 | K31: =E31/12 -> 179
B32: =IF(C32="","",SUBTOTAL(103,$C$13:C32)) -> 1 | C32: 43223-001.G (KM3.PO5.26) | D32: Giày có mũ giày bằng vật liệu dệt và đế ngoài bằng plastic, mũi giày không được gắn bảo vệ. Hàng mới 100%. | F32: đôi | G32: 1.16 | H32: 7.2 | I32: =G32*E32 -> 0 | J32: =H32*E32 -> 0 | K32: =E32/12 -> 0
A33: 16 | B33: =IF(C33="","",SUBTOTAL(103,$C$13:C33)) -> 2 | C33: 41878-0NG.G (KM3.PO5.26) | D33: Giày có mũ giày bằng vật liệu dệt và đế ngoài bằng plastic, mũi giày không được gắn bảo vệ. Hàng mới 100%. | E33: 852 | F33: đôi | G33: 1.16 | H33: 7.2 | I33: =G33*E33 -> 988.32 | J33: =H33*E33 -> 6134.4 | K33: =E33/12 -> 71
A34: 18 | B34: =IF(C34="","",SUBTOTAL(103,$C$13:C34)) -> 2 | C34: 45849-0C4.G (KM3.PO5.26) | D34: Giày có mũ giày bằng vật liệu dệt và đế ngoài bằng plastic, mũi giày không được gắn bảo vệ. Hàng mới 100%. | F34: đôi | G34: 1.16 | H34: 7.2 | I34: =G34*E34 -> 0 | J34: =H34*E34 -> 0 | K34: =E34/12 -> 0
A35: 19 | B35: =IF(C35="","",SUBTOTAL(103,$C$13:C35)) -> 2 | C35: 45849-2OG.G (KM3.PO5.26) | D35: Giày có mũ giày bằng vật liệu dệt và đế ngoài bằng plastic, mũi giày không được gắn bảo vệ. Hàng mới 100%. | F35: đôi | G35: 1.16 | H35: 7.2 | I35: =G35*E35 -> 0 | J35: =H35*E35 -> 0 | K35: =E35/12 -> 0
A36: 20 | B36: =IF(C36="","",SUBTOTAL(103,$C$13:C36)) -> 2 | C36: 45902-1YZ.G (KM3.PO5.26) | D36: Giày có mũ giày bằng vật liệu dệt và đế ngoài bằng plastic, mũi giày không được gắn bảo vệ. Hàng mới 100%. | F36: đôi | G36: 1.16 | H36: 7.2 | I36: =G36*E36 -> 0 | J36: =H36*E36 -> 0 | K36: =E36/12 -> 0
B37: =IF(C37="","",SUBTOTAL(103,$C$13:C37)) -> 2 | C37: 45862-0TA.G (KM3.PO5.26) | D37: Giày có mũ giày bằng vật liệu dệt và đế ngoài bằng plastic, mũi giày không được gắn bảo vệ. Hàng mới 100%. | F37: đôi | G37: 1.16 | H37: 7.2 | I37: =G37*E37 -> 0 | J37: =H37*E37 -> 0 | K37: =E37/12 -> 0
A38: 22 | B38: =IF(C38="","",SUBTOTAL(103,$C$13:C38)) -> 2 | C38: 45862-1ZK.G (KM3.PO5.26) | D38: Giày có mũ giày bằng vật liệu dệt và đế ngoài bằng plastic, mũi giày không được gắn bảo vệ. Hàng mới 100%. | F38: đôi | G38: 1.16 | H38: 7.2 | I38: =G38*E38 -> 0 | J38: =H38*E38 -> 0 | K38: =E38/12 -> 0
A39: 23 | B39: =IF(C39="","",SUBTOTAL(103,$C$13:C39)) -> 2 | C39: 45862-3ZZ.G (KM3.PO5.26) | D39: Giày có mũ giày bằng vật liệu dệt và đế ngoài bằng plastic, mũi giày không được gắn bảo vệ. Hàng mới 100%. | F39: đôi | G39: 1.16 | H39: 7.2 | I39: =G39*E39 -> 0 | J39: =H39*E39 -> 0 | K39: =E39/12 -> 0
B40: =IF(C40="","",SUBTOTAL(103,$C$13:C40)) -> 2 | C40: 41898-2LI (KM3.PO5.26) | D40: Giày có mũ giày bằng vật liệu dệt và đế ngoài bằng plastic, mũi giày không được gắn bảo vệ. Hàng mới 100%. | F40: đôi | G40: 1.16 | H40: 7.2 | I40: =G40*E40 -> 0 | J40: =H40*E40 -> 0
...

Sheet PKL
A1: CÔNG TY TNHH HẢI AN NEW MATERIAL HẬU GIANG
A2: SỐ 168, ẤP TẦM VU 1, XÃ THẠNH HÒA, TP CẦN THƠ, VIỆT NAM.
A3: PACKING LIST
A4: Bên thuê gia công : | C4: CÔNG TY TNHH KINGMAKER III (VIỆT NAM) FOOTWEAR | G4: INVOICE NO.: | H4: =INV!J4 -> KMHD-NEW2026-0233 | J4: KMHD-NEW2026-0050
B5: Địa chỉ : | C5: SỐ 1, ĐƯỜNG 4A, KCN VIỆT NAM SINGAPORE, | G5: DATE: | H5: =INV!J5 -> SEP 05,2026
C6: XÃ THỌ PHONG, TỈNH QUẢNG NGÃI, VIỆT NAM | G6: Hợp đồng: KM-HANEW/01-2025
G7: Điều kiện giao hàng: | H7: DAP
A8: Bên nhận gia công: | C8: CÔNG TY TNHH HẢI AN NEW MATERIAL HẬU GIANG | G8: Phương thức thanh toán: | H8: TT
B9: Địa chỉ : | C9: SỐ 168, ẤP TẦM VU 1, XÃ THẠNH HÒA | G9: Nước đến: | H9: VIETNAM
C10: TP. CẦN THƠ, VIỆT NAM
A11: STT | B11: MÃ | C11: MÔ TẢ | D11: SỐ LƯỢNG | E11: ĐVT | F11: SỐ KIỆN | G11: TRỌNG LƯỢNG (KGM) | H11: TỔNG TRỌNG LƯỢNG (KGM)
A12: =IF(F12<=0,"",(SUM($F$11:F11)+1)&"-"&SUM($F$11:F12)) | B12: 42072-030 (KM3.PO5.26) | C12: Giày có mũ giày bằng vật liệu dệt và đế ngoài bằng plastic, mũi giày không được gắn bảo vệ. Hàng mới 100%. | D12: =IF(B12="","",IF(COUNTIF($B$12:B12,B12)=1,INT(VLOOKUP(B12,INV!$C$13:$E$39,3,FALSE)/12)*12,MOD(VLOOKUP(B12,INV!$C$13:$E$39,3,FALSE),12))) -> 0 | E12: đôi | F12: =IF(D12<=0,0,IF(D12<12,1,D12/12)) -> 0 | G12: =I12*3.2 -> 0 | H12: =ROUNDUP(G12+F12*0.1,0) -> 0 | I12: =D12/12 -> 0 | J12: =F12 -> 0
A13: =IF(F13<=0,"",(SUM($F$11:F12)+1)&"-"&SUM($F$11:F13)) | B13: =B12 -> 42072-030 (KM3.PO5.26) | C13: Giày có mũ giày bằng vật liệu dệt và đế ngoài bằng plastic, mũi giày không được gắn bảo vệ. Hàng mới 100%. | D13: =IF(B13="","",IF(COUNTIF($B$12:B13,B13)=1,INT(VLOOKUP(B13,INV!$C$13:$E$39,3,FALSE)/12)*12,MOD(VLOOKUP(B13,INV!$C$13:$E$39,3,FALSE),12))) -> 0 | E13: đôi | F13: =IF(D13<=0,0,IF(D13<12,1,D13/12)) -> 0 | G13: =I13*3.2 -> 0 | H13: =ROUNDUP(G13+F13*0.1,0) -> 0 | I13: =D13/12 -> 0
A14: =IF(F14<=0,"",(SUM($F$11:F13)+1)&"-"&SUM($F$11:F14)) | B14: 42072-267 (KM3.PO5.26) | C14: Giày có mũ giày bằng vật liệu dệt và đế ngoài bằng plastic, mũi giày không được gắn bảo vệ. Hàng mới 100%. | D14: =IF(B14="","",IF(COUNTIF($B$12:B14,B14)=1,INT(VLOOKUP(B14,INV!$C$13:$E$39,3,FALSE)/12)*12,MOD(VLOOKUP(B14,INV!$C$13:$E$39,3,FALSE),12))) -> 0 | E14: đôi | F14: =IF(D14<=0,0,IF(D14<12,1,D14/12)) -> 0 | G14: =I14*3.2 -> 0 | H14: =ROUNDUP(G14+F14*0.1,0) -> 0 | I14: =D14/12 -> 0 | J14: =F14 -> 0
A15: =IF(F15<=0,"",(SUM($F$11:F14)+1)&"-"&SUM($F$11:F15)) | B15: =B14 -> 42072-267 (KM3.PO5.26) | C15: Giày có mũ giày bằng vật liệu dệt và đế ngoài bằng plastic, mũi giày không được gắn bảo vệ. Hàng mới 100%. | D15: =IF(B15="","",IF(COUNTIF($B$12:B15,B15)=1,INT(VLOOKUP(B15,INV!$C$13:$E$39,3,FALSE)/12)*12,MOD(VLOOKUP(B15,INV!$C$13:$E$39,3,FALSE),12))) -> 0 | E15: đôi | F15: =IF(D15<=0,0,IF(D15<12,1,D15/12)) -> 0 | G15: =I15*3.2 -> 0 | H15: =ROUNDUP(G15+F15*0.1,0) -> 0 | I15: =D15/12 -> 0
A16: =IF(F16<=0,"",(SUM($F$11:F15)+1)&"-"&SUM($F$11:F16)) | B16: 42072-410 (KM3.PO5.26) | C16: Giày có mũ giày bằng vật liệu dệt và đế ngoài bằng plastic, mũi giày không được gắn bảo vệ. Hàng mới 100%. | D16: =IF(B16="","",IF(COUNTIF($B$12:B16,B16)=1,INT(VLOOKUP(B16,INV!$C$13:$E$39,3,FALSE)/12)*12,MOD(VLOOKUP(B16,INV!$C$13:$E$39,3,FALSE),12))) -> 0 | E16: đôi | F16: =IF(D16<=0,0,IF(D16<12,1,D16/12)) -> 0 | G16: =I16*3.2 -> 0 | H16: =ROUNDUP(G16+F16*0.1,0) -> 0 | I16: =D16/12 -> 0 | J16: =J15+F16 -> 0
A17: =IF(F17<=0,"",(SUM($F$11:F16)+1)&"-"&SUM($F$11:F17)) | B17: =B16 -> 42072-410 (KM3.PO5.26) | C17: Giày có mũ giày bằng vật liệu dệt và đế ngoài bằng plastic, mũi giày không được gắn bảo vệ. Hàng mới 100%. | D17: =IF(B17="","",IF(COUNTIF($B$12:B17,B17)=1,INT(VLOOKUP(B17,INV!$C$13:$E$39,3,FALSE)/12)*12,MOD(VLOOKUP(B17,INV!$C$13:$E$39,3,FALSE),12))) -> 0 | E17: đôi | F17: =IF(D17<=0,0,IF(D17<12,1,D17/12)) -> 0 | G17: =I17*3.2 -> 0 | H17: =ROUNDUP(G17+F17*0.1,0) -> 0 | I17: =D17/12 -> 0
A18: =IF(F18<=0,"",(SUM($F$11:F17)+1)&"-"&SUM($F$11:F18)) | B18: 40700-060 (KM3.PO5.26) | C18: Giày có mũ giày bằng vật liệu dệt và đế ngoài bằng plastic, mũi giày không được gắn bảo vệ. Hàng mới 100%. | D18: =IF(B18="","",IF(COUNTIF($B$12:B18,B18)=1,INT(VLOOKUP(B18,INV!$C$13:$E$39,3,FALSE)/12)*12,MOD(VLOOKUP(B18,INV!$C$13:$E$39,3,FALSE),12))) -> 0 | E18: đôi | F18: =IF(D18<=0,0,IF(D18<12,1,D18/12)) -> 0 | G18: =I18*3.2 -> 0 | H18: =ROUNDUP(G18+F18*0.1,0) -> 0 | I18: =D18/12 -> 0 | J18: =J17+F18 -> 0
A19: =IF(F19<=0,"",(SUM($F$11:F18)+1)&"-"&SUM($F$11:F19)) | B19: =B18 -> 40700-060 (KM3.PO5.26) | C19: Giày có mũ giày bằng vật liệu dệt và đế ngoài bằng plastic, mũi giày không được gắn bảo vệ. Hàng mới 100%. | D19: =IF(B19="","",IF(COUNTIF($B$12:B19,B19)=1,INT(VLOOKUP(B19,INV!$C$13:$E$39,3,FALSE)/12)*12,MOD(VLOOKUP(B19,INV!$C$13:$E$39,3,FALSE),12))) -> 0 | E19: đôi | F19: =IF(D19<=0,0,IF(D19<12,1,D19/12)) -> 0 | G19: =I19*3.2 -> 0 | H19: =ROUNDUP(G19+F19*0.1,0) -> 0 | I19: =D19/12 -> 0
A20: =IF(F20<=0,"",(SUM($F$11:F19)+1)&"-"&SUM($F$11:F20)) | B20: 42073-030 (KM3.PO5.26) | C20: Giày có mũ giày bằng vật liệu dệt và đế ngoài bằng plastic, mũi giày không được gắn bảo vệ. Hàng mới 100%. | D20: =IF(B20="","",IF(COUNTIF($B$12:B20,B20)=1,INT(VLOOKUP(B20,INV!$C$13:$E$39,3,FALSE)/12)*12,MOD(VLOOKUP(B20,INV!$C$13:$E$39,3,FALSE),12))) -> 0 | E20: đôi | F20: =IF(D20<=0,0,IF(D20<12,1,D20/12)) -> 0 | G20: =I20*3.2 -> 0 | H20: =ROUNDUP(G20+F20*0.1,0) -> 0 | I20: =D20/12 -> 0 | J20: =J19+F20 -> 0
A21: =IF(F21<=0,"",(SUM($F$11:F20)+1)&"-"&SUM($F$11:F21)) | B21: =B20 -> 42073-030 (KM3.PO5.26) | C21: Giày có mũ giày bằng vật liệu dệt và đế ngoài bằng plastic, mũi giày không được gắn bảo vệ. Hàng mới 100%. | D21: =IF(B21="","",IF(COUNTIF($B$12:B21,B21)=1,INT(VLOOKUP(B21,INV!$C$13:$E$39,3,FALSE)/12)*12,MOD(VLOOKUP(B21,INV!$C$13:$E$39,3,FALSE),12))) -> 0 | E21: đôi | F21: =IF(D21<=0,0,IF(D21<12,1,D21/12)) -> 0 | G21: =I21*3.2 -> 0 | H21: =ROUNDUP(G21+F21*0.1,0) -> 0 | I21: =D21/12 -> 0
A22: =IF(F22<=0,"",(SUM($F$11:F21)+1)&"-"&SUM($F$11:F22)) | B22: 40700-007 (KM3.PO5.26) | C22: Giày có mũ giày bằng vật liệu dệt và đế ngoài bằng plastic, mũi giày không được gắn bảo vệ. Hàng mới 100%. | D22: =IF(B22="","",IF(COUNTIF($B$12:B22,B22)=1,INT(VLOOKUP(B22,INV!$C$13:$E$39,3,FALSE)/12)*12,MOD(VLOOKUP(B22,INV!$C$13:$E$39,3,FALSE),12))) -> 0 | E22: đôi | F22: =IF(D22<=0,0,IF(D22<12,1,D22/12)) -> 0 | G22: =I22*3.2 -> 0 | H22: =ROUNDUP(G22+F22*0.1,0) -> 0 | I22: =D22/12 -> 0 | J22: =J21+F22 -> 0
A23: =IF(F23<=0,"",(SUM($F$11:F22)+1)&"-"&SUM($F$11:F23)) | B23: =B22 -> 40700-007 (KM3.PO5.26) | C23: Giày có mũ giày bằng vật liệu dệt và đế ngoài bằng plastic, mũi giày không được gắn bảo vệ. Hàng mới 100%. | D23: =IF(B23="","",IF(COUNTIF($B$12:B23,B23)=1,INT(VLOOKUP(B23,INV!$C$13:$E$39,3,FALSE)/12)*12,MOD(VLOOKUP(B23,INV!$C$13:$E$39,3,FALSE),12))) -> 0 | E23: đôi | F23: =IF(D23<=0,0,IF(D23<12,1,D23/12)) -> 0 | G23: =I23*3.2 -> 0 | H23: =ROUNDUP(G23+F23*0.1,0) -> 0 | I23: =D23/12 -> 0
A24: =IF(F24<=0,"",(SUM($F$11:F23)+1)&"-"&SUM($F$11:F24)) | B24: 40700-066 (KM3.PO5.26) | C24: Giày có mũ giày bằng vật liệu dệt và đế ngoài bằng plastic, mũi giày không được gắn bảo vệ. Hàng mới 100%. | D24: =IF(B24="","",IF(COUNTIF($B$12:B24,B24)=1,INT(VLOOKUP(B24,INV!$C$13:$E$39,3,FALSE)/12)*12,MOD(VLOOKUP(B24,INV!$C$13:$E$39,3,FALSE),12))) -> 0 | E24: đôi | F24: =IF(D24<=0,0,IF(D24<12,1,D24/12)) -> 0 | G24: =I24*3.2 -> 0 | H24: =ROUNDUP(G24+F24*0.1,0) -> 0 | I24: =D24/12 -> 0 | J24: =J22+F24 -> 0
A25: =IF(F25<=0,"",(SUM($F$11:F24)+1)&"-"&SUM($F$11:F25)) | B25: =B24 -> 40700-066 (KM3.PO5.26) | C25: Giày có mũ giày bằng vật liệu dệt và đế ngoài bằng plastic, mũi giày không được gắn bảo vệ. Hàng mới 100%. | D25: =IF(B25="","",IF(COUNTIF($B$12:B25,B25)=1,INT(VLOOKUP(B25,INV!$C$13:$E$39,3,FALSE)/12)*12,MOD(VLOOKUP(B25,INV!$C$13:$E$39,3,FALSE),12))) -> 0 | E25: đôi | F25: =IF(D25<=0,0,IF(D25<12,1,D25/12)) -> 0 | G25: =I25*3.2 -> 0 | H25: =ROUNDUP(G25+F25*0.1,0) -> 0 | I25: =D25/12 -> 0
A26: =IF(F26<=0,"",(SUM($F$11:F25)+1)&"-"&SUM($F$11:F26)) | B26: 40700-410 (KM3.PO5.26) | C26: Giày có mũ giày bằng vật liệu dệt và đế ngoài bằng plastic, mũi giày không được gắn bảo vệ. Hàng mới 100%. | D26: =IF(B26="","",IF(COUNTIF($B$12:B26,B26)=1,INT(VLOOKUP(B26,INV!$C$13:$E$39,3,FALSE)/12)*12,MOD(VLOOKUP(B26,INV!$C$13:$E$39,3,FALSE),12))) -> 0 | E26: đôi | F26: =IF(D26<=0,0,IF(D26<12,1,D26/12)) -> 0 | G26: =I26*3.2 -> 0 | H26: =ROUNDUP(G26+F26*0.1,0) -> 0 | I26: =D26/12 -> 0 | J26: =J25+F26 -> 0
A27: =IF(F27<=0,"",(SUM($F$11:F26)+1)&"-"&SUM($F$11:F27)) | B27: =B26 -> 40700-410 (KM3.PO5.26) | C27: Giày có mũ giày bằng vật liệu dệt và đế ngoài bằng plastic, mũi giày không được gắn bảo vệ. Hàng mới 100%. | D27: =IF(B27="","",IF(COUNTIF($B$12:B27,B27)=1,INT(VLOOKUP(B27,INV!$C$13:$E$39,3,FALSE)/12)*12,MOD(VLOOKUP(B27,INV!$C$13:$E$39,3,FALSE),12))) -> 0 | E27: đôi | F27: =IF(D27<=0,0,IF(D27<12,1,D27/12)) -> 0 | G27: =I27*3.2 -> 0 | H27: =ROUNDUP(G27+F27*0.1,0) -> 0 | I27: =D27/12 -> 0
A28: =IF(F28<=0,"",(SUM($F$11:F27)+1)&"-"&SUM($F$11:F28)) | B28: 42072-066 (KM3.PO5.26) | C28: Giày có mũ giày bằng vật liệu dệt và đế ngoài bằng plastic, mũi giày không được gắn bảo vệ. Hàng mới 100%. | D28: =IF(B28="","",IF(COUNTIF($B$12:B28,B28)=1,INT(VLOOKUP(B28,INV!$C$13:$E$39,3,FALSE)/12)*12,MOD(VLOOKUP(B28,INV!$C$13:$E$39,3,FALSE),12))) -> 0 | E28: đôi | F28: =IF(D28<=0,0,IF(D28<12,1,D28/12)) -> 0 | G28: =I28*3.2 -> 0 | H28: =ROUNDUP(G28+F28*0.1,0) -> 0 | I28: =D28/12 -> 0 | J28: =J27+F28 -> 0
A29: =IF(F29<=0,"",(SUM($F$11:F28)+1)&"-"&SUM($F$11:F29)) | B29: =B28 -> 42072-066 (KM3.PO5.26) | C29: Giày có mũ giày bằng vật liệu dệt và đế ngoài bằng plastic, mũi giày không được gắn bảo vệ. Hàng mới 100%. | D29: =IF(B29="","",IF(COUNTIF($B$12:B29,B29)=1,INT(VLOOKUP(B29,INV!$C$13:$E$39,3,FALSE)/12)*12,MOD(VLOOKUP(B29,INV!$C$13:$E$39,3,FALSE),12))) -> 0 | E29: đôi | F29: =IF(D29<=0,0,IF(D29<12,1,D29/12)) -> 0 | G29: =I29*3.2 -> 0 | H29: =ROUNDUP(G29+F29*0.1,0) -> 0 | I29: =D29/12 -> 0
A30: =IF(F30<=0,"",(SUM($F$11:F29)+1)&"-"&SUM($F$11:F30)) | B30: 42073-060 (KM3.PO5.26) | C30: Giày có mũ giày bằng vật liệu dệt và đế ngoài bằng plastic, mũi giày không được gắn bảo vệ. Hàng mới 100%. | D30: =IF(B30="","",IF(COUNTIF($B$12:B30,B30)=1,INT(VLOOKUP(B30,INV!$C$13:$E$39,3,FALSE)/12)*12,MOD(VLOOKUP(B30,INV!$C$13:$E$39,3,FALSE),12))) -> 0 | E30: đôi | F30: =IF(D30<=0,0,IF(D30<12,1,D30/12)) -> 0 | G30: =I30*3.2 -> 0 | H30: =ROUNDUP(G30+F30*0.1,0) -> 0 | I30: =D30/12 -> 0 | J30: =J29+F30 -> 0
A31: =IF(F31<=0,"",(SUM($F$11:F30)+1)&"-"&SUM($F$11:F31)) | B31: =B30 -> 42073-060 (KM3.PO5.26) | C31: Giày có mũ giày bằng vật liệu dệt và đế ngoài bằng plastic, mũi giày không được gắn bảo vệ. Hàng mới 100%. | D31: =IF(B31="","",IF(COUNTIF($B$12:B31,B31)=1,INT(VLOOKUP(B31,INV!$C$13:$E$39,3,FALSE)/12)*12,MOD(VLOOKUP(B31,INV!$C$13:$E$39,3,FALSE),12))) -> 0 | E31: đôi | F31: =IF(D31<=0,0,IF(D31<12,1,D31/12)) -> 0 | G31: =I31*3.2 -> 0 | H31: =ROUNDUP(G31+F31*0.1,0) -> 0 | I31: =D31/12 -> 0
A32: =IF(F32<=0,"",(SUM($F$11:F31)+1)&"-"&SUM($F$11:F32)) | B32: 42073-410 (KM3.PO5.26) | C32: Giày có mũ giày bằng vật liệu dệt và đế ngoài bằng plastic, mũi giày không được gắn bảo vệ. Hàng mới 100%. | D32: =IF(B32="","",IF(COUNTIF($B$12:B32,B32)=1,INT(VLOOKUP(B32,INV!$C$13:$E$39,3,FALSE)/12)*12,MOD(VLOOKUP(B32,INV!$C$13:$E$39,3,FALSE),12))) -> 0 | E32: đôi | F32: =IF(D32<=0,0,IF(D32<12,1,D32/12)) -> 0 | G32: =I32*3.2 -> 0 | H32: =ROUNDUP(G32+F32*0.1,0) -> 0 | I32: =D32/12 -> 0
A33: =IF(F33<=0,"",(SUM($F$11:F32)+1)&"-"&SUM($F$11:F33)) | B33: =B32 -> 42073-410 (KM3.PO5.26) | C33: Giày có mũ giày bằng vật liệu dệt và đế ngoài bằng plastic, mũi giày không được gắn bảo vệ. Hàng mới 100%. | D33: =IF(B33="","",IF(COUNTIF($B$12:B33,B33)=1,INT(VLOOKUP(B33,INV!$C$13:$E$39,3,FALSE)/12)*12,MOD(VLOOKUP(B33,INV!$C$13:$E$39,3,FALSE),12))) -> 0 | E33: đôi | F33: =IF(D33<=0,0,IF(D33<12,1,D33/12)) -> 0 | G33: =I33*3.2 -> 0 | H33: =ROUNDUP(G33+F33*0.1,0) -> 0 | I33: =D33/12 -> 0
A34: =IF(F34<=0,"",(SUM($F$11:F33)+1)&"-"&SUM($F$11:F34)) | B34: 42072-060 (KM3.PO5.26) | C34: Giày có mũ giày bằng vật liệu dệt và đế ngoài bằng plastic, mũi giày không được gắn bảo vệ. Hàng mới 100%. | D34: =IF(B34="","",IF(COUNTIF($B$12:B34,B34)=1,INT(VLOOKUP(B34,INV!$C$13:$E$39,3,FALSE)/12)*12,MOD(VLOOKUP(B34,INV!$C$13:$E$39,3,FALSE),12))) -> 0 | E34: đôi | F34: =IF(D34<=0,0,IF(D34<12,1,D34/12)) -> 0 | G34: =I34*3.2 -> 0 | H34: =ROUNDUP(G34+F34*0.1,0) -> 0 | I34: =D34/12 -> 0
A35: =IF(F35<=0,"",(SUM($F$11:F34)+1)&"-"&SUM($F$11:F35)) | B35: =B34 -> 42072-060 (KM3.PO5.26) | C35: Giày có mũ giày bằng vật liệu dệt và đế ngoài bằng plastic, mũi giày không được gắn bảo vệ. Hàng mới 100%. | D35: =IF(B35="","",IF(COUNTIF($B$12:B35,B35)=1,INT(VLOOKUP(B35,INV!$C$13:$E$39,3,FALSE)/12)*12,MOD(VLOOKUP(B35,INV!$C$13:$E$39,3,FALSE),12))) -> 0 | E35: đôi | F35: =IF(D35<=0,0,IF(D35<12,1,D35/12)) -> 0 | G35: =I35*3.2 -> 0 | H35: =ROUNDUP(G35+F35*0.1,0) -> 0 | I35: =D35/12 -> 0
A36: =IF(F36<=0,"",(SUM($F$11:F35)+1)&"-"&SUM($F$11:F36)) | B36: 45187-1WQ (KM3.PO5.26) | C36: Giày có mũ giày bằng vật liệu dệt và đế ngoài bằng plastic, mũi giày không được gắn bảo vệ. Hàng mới 100%. | D36: =IF(B36="","",IF(COUNTIF($B$12:B36,B36)=1,INT(VLOOKUP(B36,INV!$C$13:$E$39,3,FALSE)/12)*12,MOD(VLOOKUP(B36,INV!$C$13:$E$39,3,FALSE),12))) -> 0 | E36: đôi | F36: =IF(D36<=0,0,IF(D36<12,1,D36/12)) -> 0 | G36: =I36*3.2 -> 0 | H36: =ROUNDUP(G36+F36*0.1,0) -> 0 | I36: =D36/12 -> 0
A37: =IF(F37<=0,"",(SUM($F$11:F36)+1)&"-"&SUM($F$11:F37)) | B37: =B36 -> 45187-1WQ (KM3.PO5.26) | C37: Giày có mũ giày bằng vật liệu dệt và đế ngoài bằng plastic, mũi giày không được gắn bảo vệ. Hàng mới 100%. | D37: =IF(B37="","",IF(COUNTIF($B$12:B37,B37)=1,INT(VLOOKUP(B37,INV!$C$13:$E$39,3,FALSE)/12)*12,MOD(VLOOKUP(B37,INV!$C$13:$E$39,3,FALSE),12))) -> 0 | E37: đôi | F37: =IF(D37<=0,0,IF(D37<12,1,D37/12)) -> 0 | G37: =I37*3.2 -> 0 | H37: =ROUNDUP(G37+F37*0.1,0) -> 0 | I37: =D37/12 -> 0
A38: =IF(F38<=0,"",(SUM($F$11:F37)+1)&"-"&SUM($F$11:F38)) | B38: 45187-3AW (KM3.PO5.26) | C38: Giày có mũ giày bằng vật liệu dệt và đế ngoài bằng plastic, mũi giày không được gắn bảo vệ. Hàng mới 100%. | D38: =IF(B38="","",IF(COUNTIF($B$12:B38,B38)=1,INT(VLOOKUP(B38,INV!$C$13:$E$39,3,FALSE)/12)*12,MOD(VLOOKUP(B38,INV!$C$13:$E$39,3,FALSE),12))) -> 0 | E38: đôi | F38: =IF(D38<=0,0,IF(D38<12,1,D38/12)) -> 0 | G38: =I38*3.2 -> 0 | H38: =ROUNDUP(G38+F38*0.1,0) -> 0 | I38: =D38/12 -> 0
A39: =IF(F39<=0,"",(SUM($F$11:F38)+1)&"-"&SUM($F$11:F39)) | B39: =B38 -> 45187-3AW (KM3.PO5.26) | C39: Giày có mũ giày bằng vật liệu dệt và đế ngoài bằng plastic, mũi giày không được gắn bảo vệ. Hàng mới 100%. | D39: =IF(B39="","",IF(COUNTIF($B$12:B39,B39)=1,INT(VLOOKUP(B39,INV!$C$13:$E$39,3,FALSE)/12)*12,MOD(VLOOKUP(B39,INV!$C$13:$E$39,3,FALSE),12))) -> 0 | E39: đôi | F39: =IF(D39<=0,0,IF(D39<12,1,D39/12)) -> 0 | G39: =I39*3.2 -> 0 | H39: =ROUNDUP(G39+F39*0.1,0) -> 0 | I39: =D39/12 -> 0
A40: =IF(F40<=0,"",(SUM($F$11:F39)+1)&"-"&SUM($F$11:F40)) | B40: 42073-066 (KM3.PO5.26) | C40: Giày có mũ giày bằng vật liệu dệt và đế ngoài bằng plastic, mũi giày không được gắn bảo vệ. Hàng mới 100%. | D40: =IF(B40="","",IF(COUNTIF($B$12:B40,B40)=1,INT(VLOOKUP(B40,INV!$C$13:$E$39,3,FALSE)/12)*12,MOD(VLOOKUP(B40,INV!$C$13:$E$39,3,FALSE),12))) -> 0 | E40: đôi | F40: =IF(D40<=0,0,IF(D40<12,1,D40/12)) -> 0 | G40: =I40*3.2 -> 0 | H40: =ROUNDUP(G40+F40*0.1,0) -> 0 | I40: =D40/12 -> 0
...

Sheet Sheet2
A1: 42072-030 | B1: (KM3.PO5.26) | C1: 42072-030 (KM3.PO5.26) | D1: 3.2 | E1: 8.2 | F1: Giày có mũ giày bằng vật liệu dệt và đế ngoài bằng plastic, mũi giày không được gắn bảo vệ (Đơn giá gia công:3.2 USD/đôi). Hàng mới 100%. | G1: PR | H1: 64041990
A2: 42072-267 | B2: (KM3.PO5.26) | C2: 42072-267 (KM3.PO5.26) | D2: 3.2 | E2: 8.2 | F2: Giày có mũ giày bằng vật liệu dệt và đế ngoài bằng plastic, mũi giày không được gắn bảo vệ (Đơn giá gia công:3.2 USD/đôi). Hàng mới 100%. | G2: PR | H2: 64041990
A3: 42072-410 | B3: (KM3.PO5.26) | C3: 42072-410 (KM3.PO5.26) | D3: 3.2 | E3: 8.2 | F3: Giày có mũ giày bằng vật liệu dệt và đế ngoài bằng plastic, mũi giày không được gắn bảo vệ (Đơn giá gia công:3.2 USD/đôi). Hàng mới 100%. | G3: PR | H3: 64041990
A4: 40700-060 | B4: (KM3.PO5.26) | C4: 40700-060 (KM3.PO5.26) | D4: 3 | E4: 8.1 | F4: Giày có mũ giày bằng vật liệu dệt và đế ngoài bằng plastic, mũi giày không được gắn bảo vệ (Đơn giá gia công:3 USD/đôi). Hàng mới 100%. | G4: PR | H4: 64041990
A5: 42073-030 | B5: (KM3.PO5.26) | C5: 42073-030 (KM3.PO5.26) | D5: 3.2 | E5: 8.2 | F5: Giày có mũ giày bằng vật liệu dệt và đế ngoài bằng plastic, mũi giày không được gắn bảo vệ (Đơn giá gia công:3.2 USD/đôi). Hàng mới 100%. | G5: PR | H5: 64041990
A6: 40700-007 | B6: (KM3.PO5.26) | C6: 40700-007 (KM3.PO5.26) | D6: 3 | E6: 8.1 | F6: Giày có mũ giày bằng vật liệu dệt và đế ngoài bằng plastic, mũi giày không được gắn bảo vệ (Đơn giá gia công:3 USD/đôi). Hàng mới 100%. | G6: PR | H6: 64041990
A7: 40700-066 | B7: (KM3.PO5.26) | C7: 40700-066 (KM3.PO5.26) | D7: 3 | E7: 8.1 | F7: Giày có mũ giày bằng vật liệu dệt và đế ngoài bằng plastic, mũi giày không được gắn bảo vệ (Đơn giá gia công:3 USD/đôi). Hàng mới 100%. | G7: PR | H7: 64041990
A8: 40700-410 | B8: (KM3.PO5.26) | C8: 40700-410 (KM3.PO5.26) | D8: 3 | E8: 8.1 | F8: Giày có mũ giày bằng vật liệu dệt và đế ngoài bằng plastic, mũi giày không được gắn bảo vệ (Đơn giá gia công:3 USD/đôi). Hàng mới 100%. | G8: PR | H8: 64041990
A9: 42072-066 | B9: (KM3.PO5.26) | C9: 42072-066 (KM3.PO5.26) | D9: 3.2 | E9: 8.2 | F9: Giày có mũ giày bằng vật liệu dệt và đế ngoài bằng plastic, mũi giày không được gắn bảo vệ (Đơn giá gia công:3.2 USD/đôi). Hàng mới 100%. | G9: PR | H9: 64041990
A10: 42073-060 | B10: (KM3.PO5.26) | C10: 42073-060 (KM3.PO5.26) | D10: 3.2 | E10: 8.2 | F10: Giày có mũ giày bằng vật liệu dệt và đế ngoài bằng plastic, mũi giày không được gắn bảo vệ (Đơn giá gia công:3.2 USD/đôi). Hàng mới 100%. | G10: PR | H10: 64041990
A11: 42073-410 | B11: (KM3.PO5.26) | C11: 42073-410 (KM3.PO5.26) | D11: 3.2 | E11: 8.2 | F11: Giày có mũ giày bằng vật liệu dệt và đế ngoài bằng plastic, mũi giày không được gắn bảo vệ (Đơn giá gia công:3.2 USD/đôi). Hàng mới 100%. | G11: PR | H11: 64041990
A12: 42072-060 | B12: (KM3.PO5.26) | C12: 42072-060 (KM3.PO5.26) | D12: 3.2 | E12: 8.2 | F12: Giày có mũ giày bằng vật liệu dệt và đế ngoài bằng plastic, mũi giày không được gắn bảo vệ (Đơn giá gia công:3.2 USD/đôi). Hàng mới 100%. | G12: PR | H12: 64041990
... A36: 45959-255 | B36: (KM3.PO5.26) | C36: 45959-255 (KM3.PO5.26) | D36: 1.16 | E36: 7.2 | F36: Giày có mũ giày bằng vật liệu dệt và đế ngoài bằng plastic, mũi giày không được gắn bảo vệ (Đơn giá gia công:1.16 USD/đôi). Hàng mới 100%. | G36: PR | H36: 64041990

Sheet Sheet1 (2)
C1: MÃ HÀNG | D1: CMT | E1: FOB
A2: 40700-007 | B2: (KM3.PO4.26) | C2: =A2&B2 -> 40700-007 (KM3.PO4.26) | D2: =VLOOKUP(A2,[1]Sheet1!A$2:D$31,4,0) -> 3 | E2: =VLOOKUP(A2,[1]Sheet1!A$2:E$31,5,0) -> 8.1 | F2: 4 | G2: =C2 -> 40700-007 (KM3.PO4.26) | H2: Giày có mũ giày bằng vật liệu dệt và đế ngoài bằng plastic, mũi giày không được gắn bảo vệ (Đơn giá gia công:3.0 USD/đôi). Hàng mới 100%. | I2: PR | J2: 64041990
A3: 40700-060 | B3: (KM3.PO4.26) | C3: =A3&B3 -> 40700-060 (KM3.PO4.26) | D3: =VLOOKUP(A3,[1]Sheet1!A$2:D$31,4,0) -> 3 | E3: =VLOOKUP(A3,[1]Sheet1!A$2:E$31,5,0) -> 8.1 | F3: 4 | G3: =C3 -> 40700-060 (KM3.PO4.26) | H3: Giày có mũ giày bằng vật liệu dệt và đế ngoài bằng plastic, mũi giày không được gắn bảo vệ (Đơn giá gia công:3.0 USD/đôi). Hàng mới 100%. | I3: PR | J3: 64041990
A4: 40700-066 | B4: (KM3.PO4.26) | C4: =A4&B4 -> 40700-066 (KM3.PO4.26) | D4: =VLOOKUP(A4,[1]Sheet1!A$2:D$31,4,0) -> 3 | E4: =VLOOKUP(A4,[1]Sheet1!A$2:E$31,5,0) -> 8.1 | F4: 4 | G4: =C4 -> 40700-066 (KM3.PO4.26) | H4: Giày có mũ giày bằng vật liệu dệt và đế ngoài bằng plastic, mũi giày không được gắn bảo vệ (Đơn giá gia công:3.0 USD/đôi). Hàng mới 100%. | I4: PR | J4: 64041990
A5: 40700-143 | B5: (KM3.PO4.26) | C5: =A5&B5 -> 40700-143 (KM3.PO4.26) | D5: =VLOOKUP(A5,[1]Sheet1!A$2:D$31,4,0) -> 3 | E5: =VLOOKUP(A5,[1]Sheet1!A$2:E$31,5,0) -> 8.1 | F5: 4 | G5: =C5 -> 40700-143 (KM3.PO4.26) | H5: Giày có mũ giày bằng vật liệu dệt và đế ngoài bằng plastic, mũi giày không được gắn bảo vệ (Đơn giá gia công:3.0 USD/đôi). Hàng mới 100%. | I5: PR | J5: 64041990
A6: 40700-410 | B6: (KM3.PO4.26) | C6: =A6&B6 -> 40700-410 (KM3.PO4.26) | D6: =VLOOKUP(A6,[1]Sheet1!A$2:D$31,4,0) -> 3 | E6: =VLOOKUP(A6,[1]Sheet1!A$2:E$31,5,0) -> 8.1 | F6: 4 | G6: =C6 -> 40700-410 (KM3.PO4.26) | H6: Giày có mũ giày bằng vật liệu dệt và đế ngoài bằng plastic, mũi giày không được gắn bảo vệ (Đơn giá gia công:3.0 USD/đôi). Hàng mới 100%. | I6: PR | J6: 64041990
A7: 41878-0NG | B7: (KM3.PO4.26) | C7: =A7&B7 -> 41878-0NG (KM3.PO4.26) | F7: 4 | G7: =C7 -> 41878-0NG (KM3.PO4.26) | H7: Giày có mũ giày bằng vật liệu dệt và đế ngoài bằng plastic, mũi giày không được gắn bảo vệ (Đơn giá gia công:3.0 USD/đôi). Hàng mới 100%. | I7: PR | J7: 64041990
A8: 42072-030 | B8: (KM3.PO4.26) | C8: =A8&B8 -> 42072-030 (KM3.PO4.26) | D8: =VLOOKUP(A8,[1]Sheet1!A$2:D$31,4,0) -> 3.2 | E8: =VLOOKUP(A8,[1]Sheet1!A$2:E$31,5,0) -> 8.2 | F8: 4 | G8: =C8 -> 42072-030 (KM3.PO4.26) | H8: Giày có mũ giày bằng vật liệu dệt và đế ngoài bằng plastic, mũi giày không được gắn bảo vệ (Đơn giá gia công:3.0 USD/đôi). Hàng mới 100%. | I8: PR | J8: 64041990
A9: 42072-1ZI | B9: (KM3.PO4.26) | C9: =A9&B9 -> 42072-1ZI (KM3.PO4.26) | D9: =VLOOKUP(A9,[1]Sheet1!A$2:D$31,4,0) -> 3.19 | E9: =VLOOKUP(A9,[1]Sheet1!A$2:E$31,5,0) -> 8.2 | F9: 4 | G9: =C9 -> 42072-1ZI (KM3.PO4.26) | H9: Giày có mũ giày bằng vật liệu dệt và đế ngoài bằng plastic, mũi giày không được gắn bảo vệ (Đơn giá gia công:3.2 USD/đôi). Hàng mới 100%. | I9: PR | J9: 64041990
A10: 42072-267 | B10: (KM3.PO4.26) | C10: =A10&B10 -> 42072-267 (KM3.PO4.26) | D10: =VLOOKUP(A10,[1]Sheet1!A$2:D$31,4,0) -> 3.2 | E10: =VLOOKUP(A10,[1]Sheet1!A$2:E$31,5,0) -> 8.2 | F10: 4 | G10: =C10 -> 42072-267 (KM3.PO4.26) | H10: Giày có mũ giày bằng vật liệu dệt và đế ngoài bằng plastic, mũi giày không được gắn bảo vệ (Đơn giá gia công:3.2 USD/đôi). Hàng mới 100%. | I10: PR | J10: 64041990
A11: 42072-410 | B11: (KM3.PO4.26) | C11: =A11&B11 -> 42072-410 (KM3.PO4.26) | D11: =VLOOKUP(A11,[1]Sheet1!A$2:D$31,4,0) -> 3.2 | E11: =VLOOKUP(A11,[1]Sheet1!A$2:E$31,5,0) -> 8.2 | F11: 4 | G11: =C11 -> 42072-410 (KM3.PO4.26) | H11: Giày có mũ giày bằng vật liệu dệt và đế ngoài bằng plastic, mũi giày không được gắn bảo vệ (Đơn giá gia công:3.2 USD/đôi). Hàng mới 100%. | I11: PR | J11: 64041990
A12: 42073-030 | B12: (KM3.PO4.26) | C12: =A12&B12 -> 42073-030 (KM3.PO4.26) | D12: =VLOOKUP(A12,[1]Sheet1!A$2:D$31,4,0) -> 3.2 | E12: =VLOOKUP(A12,[1]Sheet1!A$2:E$31,5,0) -> 8.2 | F12: 4 | G12: =C12 -> 42073-030 (KM3.PO4.26) | H12: Giày có mũ giày bằng vật liệu dệt và đế ngoài bằng plastic, mũi giày không được gắn bảo vệ (Đơn giá gia công:3.2 USD/đôi). Hàng mới 100%. | I12: PR | J12: 64041990
A13: 42073-060 | B13: (KM3.PO4.26) | C13: =A13&B13 -> 42073-060 (KM3.PO4.26) | D13: =VLOOKUP(A13,[1]Sheet1!A$2:D$31,4,0) -> 3.2 | E13: =VLOOKUP(A13,[1]Sheet1!A$2:E$31,5,0) -> 8.2 | F13: 4 | G13: =C13 -> 42073-060 (KM3.PO4.26) | H13: Giày có mũ giày bằng vật liệu dệt và đế ngoài bằng plastic, mũi giày không được gắn bảo vệ (Đơn giá gia công:3.19 USD/đôi). Hàng mới 100%. | I13: PR | J13: 64041990
A14: 42073-267 | B14: (KM3.PO4.26) | C14: =A14&B14 -> 42073-267 (KM3.PO4.26) | D14: =VLOOKUP(A14,[1]Sheet1!A$2:D$31,4,0) -> 3.2 | E14: =VLOOKUP(A14,[1]Sheet1!A$2:E$31,5,0) -> 8.2 | F14: 4 | G14: =C14 -> 42073-267 (KM3.PO4.26) | H14: Giày có mũ giày bằng vật liệu dệt và đế ngoài bằng plastic, mũi giày không được gắn bảo vệ (Đơn giá gia công:3.2 USD/đôi). Hàng mới 100%. | I14: PR | J14: 64041990
A15: 42073-410 | B15: (KM3.PO4.26) | C15: =A15&B15 -> 42073-410 (KM3.PO4.26) | D15: =VLOOKUP(A15,[1]Sheet1!A$2:D$31,4,0) -> 3.2 | E15: =VLOOKUP(A15,[1]Sheet1!A$2:E$31,5,0) -> 8.2 | F15: 4 | G15: =C15 -> 42073-410 (KM3.PO4.26) | H15: Giày có mũ giày bằng vật liệu dệt và đế ngoài bằng plastic, mũi giày không được gắn bảo vệ (Đơn giá gia công:3.2 USD/đôi). Hàng mới 100%. | I15: PR | J15: 64041990
A16: 43223-001 | B16: (KM3.PO4.26) | C16: =A16&B16 -> 43223-001 (KM3.PO4.26) | F16: 4 | G16: =C16 -> 43223-001 (KM3.PO4.26) | H16: Giày có mũ giày bằng vật liệu dệt và đế ngoài bằng plastic, mũi giày không được gắn bảo vệ (Đơn giá gia công:3.2 USD/đôi). Hàng mới 100%. | I16: PR | J16: 64041990
A17: 44599-0PF | B17: (KM3.PO4.26) | C17: =A17&B17 -> 44599-0PF (KM3.PO4.26) | D17: 1.16 | E17: 7 | G17: =C17 -> 44599-0PF (KM3.PO4.26) | H17: Giày có mũ giày bằng vật liệu dệt và đế ngoài bằng plastic, mũi giày không được gắn bảo vệ (Đơn giá gia công:3.2 USD/đôi). Hàng mới 100%. | I17: PR | J17: 64041990
A18: 44599-2KY | B18: (KM3.PO4.26) | C18: =A18&B18 -> 44599-2KY (KM3.PO4.26) | D18: 1.16 | E18: 7 | G18: =C18 -> 44599-2KY (KM3.PO4.26) | H18: Giày có mũ giày bằng vật liệu dệt và đế ngoài bằng plastic, mũi giày không được gắn bảo vệ (Đơn giá gia công:3.2 USD/đôi). Hàng mới 100%. | I18: PR | J18: 64041990
A19: 44599-2KZ | B19: (KM3.PO4.26) | C19: =A19&B19 -> 44599-2KZ (KM3.PO4.26) | D19: 1.16 | E19: 7 | F19: 4 | G19: =C19 -> 44599-2KZ (KM3.PO4.26) | H19: Giày có mũ giày bằng vật liệu dệt và đế ngoài bằng plastic, mũi giày không được gắn bảo vệ (Đơn giá gia công:3.2 USD/đôi). Hàng mới 100%. | I19: PR | J19: 64041990
A20: 45187-1WQ | B20: (KM3.PO4.26) | C20: =A20&B20 -> 45187-1WQ (KM3.PO4.26) | D20: =VLOOKUP(A20,[1]Sheet1!A$2:D$31,4,0) -> 3.02 | E20: =VLOOKUP(A20,[1]Sheet1!A$2:E$31,5,0) -> 8.2 | F20: 4 | G20: =C20 -> 45187-1WQ (KM3.PO4.26) | H20: Giày có mũ giày bằng vật liệu dệt và đế ngoài bằng plastic, mũi giày không được gắn bảo vệ (Đơn giá gia công:3.2 USD/đôi). Hàng mới 100%. | I20: PR | J20: 64041990
A21: 45187-3AW | B21: (KM3.PO4.26) | C21: =A21&B21 -> 45187-3AW (KM3.PO4.26) | D21: =VLOOKUP(A21,[1]Sheet1!A$2:D$31,4,0) -> 3.02 | E21: =VLOOKUP(A21,[1]Sheet1!A$2:E$31,5,0) -> 8.2 | F21: 4 | G21: =C21 -> 45187-3AW (KM3.PO4.26) | H21: Giày có mũ giày bằng vật liệu dệt và đế ngoài bằng plastic, mũi giày không được gắn bảo vệ (Đơn giá gia công:2.99 USD/đôi). Hàng mới 100%. | I21: PR | J21: 64041990
A22: 45187-4ZV | B22: (KM3.PO4.26) | C22: =A22&B22 -> 45187-4ZV (KM3.PO4.26) | D22: =VLOOKUP(A22,[1]Sheet1!A$2:D$31,4,0) -> 3.02 | E22: =VLOOKUP(A22,[1]Sheet1!A$2:E$31,5,0) -> 8.2 | F22: 4 | G22: =C22 -> 45187-4ZV (KM3.PO4.26) | H22: Giày có mũ giày bằng vật liệu dệt và đế ngoài bằng plastic, mũi giày không được gắn bảo vệ (Đơn giá gia công:3.02 USD/đôi). Hàng mới 100%. | I22: PR | J22: 64041990
A23: 45414-0CU | B23: (KM3.PO4.26) | C23: =A23&B23 -> 45414-0CU (KM3.PO4.26) | D23: =VLOOKUP(A23,[1]Sheet1!A$2:D$31,4,0) -> 3.02 | E23: =VLOOKUP(A23,[1]Sheet1!A$2:E$31,5,0) -> 8.4 | G23: =C23 -> 45414-0CU (KM3.PO4.26) | H23: Giày có mũ giày bằng vật liệu dệt và đế ngoài bằng plastic, mũi giày không được gắn bảo vệ (Đơn giá gia công:3.02 USD/đôi). Hàng mới 100%. | I23: PR | J23: 64041990
A24: 45428-2LX | B24: (KM3.PO4.26) | C24: =A24&B24 -> 45428-2LX (KM3.PO4.26) | D24: 3 | E24: 8.1 | F24: 4 | G24: =C24 -> 45428-2LX (KM3.PO4.26) | H24: Giày có mũ giày bằng vật liệu dệt và đế ngoài bằng plastic, mũi giày không được gắn bảo vệ (Đơn giá gia công:3.02 USD/đôi). Hàng mới 100%. | I24: PR | J24: 64041990
A25: 45777-7BR | B25: (KM3.PO4.26) | C25: =A25&B25 -> 45777-7BR (KM3.PO4.26) | D25: =VLOOKUP(A25,[1]Sheet1!A$2:D$31,4,0) -> 2.99 | E25: =VLOOKUP(A25,[1]Sheet1!A$2:E$31,5,0) -> 8 | F25: 4 | G25: =C25 -> 45777-7BR (KM3.PO4.26) | H25: Giày có mũ giày bằng vật liệu dệt và đế ngoài bằng plastic, mũi giày không được gắn bảo vệ (Đơn giá gia công:3.02 USD/đôi). Hàng mới 100%. | I25: PR | J25: 64041990
A26: 45849-0C4 | B26: (KM3.PO4.26) | C26: =A26&B26 -> 45849-0C4 (KM3.PO4.26) | G26: =C26 -> 45849-0C4 (KM3.PO4.26) | H26: Giày có mũ giày bằng vật liệu dệt và đế ngoài bằng plastic, mũi giày không được gắn bảo vệ (Đơn giá gia công:3.02 USD/đôi). Hàng mới 100%. | I26: PR | J26: 64041990
A27: 45849-2OG | B27: (KM3.PO4.26) | C27: =A27&B27 -> 45849-2OG (KM3.PO4.26) | G27: =C27 -> 45849-2OG (KM3.PO4.26) | H27: Giày có mũ giày bằng vật liệu dệt và đế ngoài bằng plastic, mũi giày không được gắn bảo vệ (Đơn giá gia công:2.99 USD/đôi). Hàng mới 100%. | I27: PR | J27: 64041990
A28: 45862-0TA | B28: (KM3.PO4.26) | C28: =A28&B28 -> 45862-0TA (KM3.PO4.26) | G28: =C28 -> 45862-0TA (KM3.PO4.26) | H28: Giày có mũ giày bằng vật liệu dệt và đế ngoài bằng plastic, mũi giày không được gắn bảo vệ (Đơn giá gia công:3.0 USD/đôi). Hàng mới 100%. | I28: PR | J28: 64041990
A29: 45862-1ZK | B29: (KM3.PO4.26) | C29: =A29&B29 -> 45862-1ZK (KM3.PO4.26) | G29: =C29 -> 45862-1ZK (KM3.PO4.26) | H29: Giày có mũ giày bằng vật liệu dệt và đế ngoài bằng plastic, mũi giày không được gắn bảo vệ (Đơn giá gia công:3.0 USD/đôi). Hàng mới 100%. | I29: PR | J29: 64041990
A30: 45862-3ZZ | B30: (KM3.PO4.26) | C30: =A30&B30 -> 45862-3ZZ (KM3.PO4.26) | G30: =C30 -> 45862-3ZZ (KM3.PO4.26)
A31: 45865-0C4 | B31: (KM3.PO4.26) | C31: =A31&B31 -> 45865-0C4 (KM3.PO4.26) | D31: =VLOOKUP(A31,[1]Sheet1!A$2:D$31,4,0) -> 3 | E31: =VLOOKUP(A31,[1]Sheet1!A$2:E$31,5,0) -> 8.1 | G31: =C31 -> 45865-0C4 (KM3.PO4.26)
A32: 45865-2NX | B32: (KM3.PO4.26) | C32: =A32&B32 -> 45865-2NX (KM3.PO4.26) | D32: =VLOOKUP(A32,[1]Sheet1!A$2:D$31,4,0) -> 3 | E32: =VLOOKUP(A32,[1]Sheet1!A$2:E$31,5,0) -> 8.1 | G32: =C32 -> 45865-2NX (KM3.PO4.26)
A33: 45866-2OC | B33: (KM3.PO4.26) | C33: =A33&B33 -> 45866-2OC (KM3.PO4.26) | G33: =C33 -> 45866-2OC (KM3.PO4.26)
A34: 45868-0C4 | B34: (KM3.PO4.26) | C34: =A34&B34 -> 45868-0C4 (KM3.PO4.26) | G34: =C34 -> 45868-0C4 (KM3.PO4.26)
A35: 45875-001 | B35: (KM3.PO4.26) | C35: =A35&B35 -> 45875-001 (KM3.PO4.26) | G35: =C35 -> 45875-001 (KM3.PO4.26)
A36: 45876-0C4 | B36: (KM3.PO4.26) | C36: =A36&B36 -> 45876-0C4 (KM3.PO4.26) | G36: =C36 -> 45876-0C4 (KM3.PO4.26)
A37: 45876-0OE | B37: (KM3.PO4.26) | C37: =A37&B37 -> 45876-0OE (KM3.PO4.26) | G37: =C37 -> 45876-0OE (KM3.PO4.26)
A38: 45906-0SM | B38: (KM3.PO4.26) | C38: =A38&B38 -> 45906-0SM (KM3.PO4.26) | G38: =C38 -> 45906-0SM (KM3.PO4.26)
A39: 45906-4UX | B39: (KM3.PO4.26) | C39: =A39&B39 -> 45906-4UX (KM3.PO4.26) | G39: =C39 -> 45906-4UX (KM3.PO4.26)
A41: 44259-265 | B41: .M (KM3.PO3.26) | C41: =A41&B41 -> 44259-265.M (KM3.PO3.26) | D41: 2.23 | E41: 7.5 | G41: =C41 -> 44259-265.M (KM3.PO3.26) | H41: Mũ giày bằng vật liệu dệt (đơn giá gia công: 2.23usd/đôi). hàng mới 100%. | I41: PR | J41: 64061090
...
